<!--URDF generated by ONSHAPE BY PTC INC, 1.217-->
<robot name="main_assembly">
    <link name="hip_joint_aluminium_rect_v13">
        <inertial>
            <mass value="0.000342908" />
            <origin xyz="-0.018365 4.33936e-05 0.0184773" rpy="0 -0 0" />
            <inertia ixx="1.82126e-06" ixy="-1.93617e-10" ixz="6.78579e-08" iyy="1.01804e-06" iyz="-1.30209e-10" izz="9.20107e-07" />
        </inertial>
        <visual>
            <origin xyz="0 0 0.08" rpy="0 -0 0" />
            <geometry>
                <mesh filename="package://main_assembly/meshes/hip_joint_aluminium_rect_v13.stl" scale="1 1 1" />
            </geometry>
            <material name="0.964706_0.964706_0.952941_0.000000_0.000000">
                <color rgba="0.964706 0.964706 0.952941 1" />
            </material>
        </visual>
    </link>
    <link name="hip_joint_aluminium_rect_v13_1">
        <inertial>
            <mass value="0.000343096" />
            <origin xyz="0.0183779 4.33682e-05 -0.0615329" rpy="0 -0 0" />
            <inertia ixx="1.82248e-06" ixy="1.93821e-10" ixz="-6.77754e-08" iyy="1.01885e-06" iyz="-1.30337e-10" izz="9.20651e-07" />
        </inertial>
        <visual>
            <origin xyz="0 0 0" rpy="0 -0 0" />
            <geometry>
                <mesh filename="package://main_assembly/meshes/hip_joint_aluminium_rect_v13_1.stl" scale="1 1 1" />
            </geometry>
            <material name="0.964706_0.964706_0.952941_0.000000_0.000000">
                <color rgba="0.964706 0.964706 0.952941 1" />
            </material>
        </visual>
    </link>
    <link name="part_1">
        <inertial>
            <mass value="1.44519" />
            <origin xyz="-5.14675e-20 -0.0155742 7.67044e-19" rpy="0 -0 0" />
            <inertia ixx="0.00149915" ixy="0" ixz="0" iyy="0.0023982" iyz="0" izz="0.00147356" />
        </inertial>
        <visual>
            <origin xyz="0 0 -3.67394e-18" rpy="0 -0 0" />
            <geometry>
                <mesh filename="package://main_assembly/meshes/Part_1.stl" scale="1 1 1" />
            </geometry>
            <material name="0.000000_0.000000_0.000000_0.000000_0.000000">
                <color rgba="0 0 0 1" />
            </material>
        </visual>
    </link>
    <link name="part_1_1">
        <inertial>
            <mass value="0.190836" />
            <origin xyz="-0.0425 -2.56394e-13 0.0195886" rpy="0 -0 0" />
            <inertia ixx="5.87597e-05" ixy="1.41175e-14" ixz="0" iyy="0.000682215" iyz="0" izz="0.000651498" />
        </inertial>
        <visual>
            <origin xyz="-0.0425 0.015 0.005" rpy="0 -0 0" />
            <geometry>
                <mesh filename="package://main_assembly/meshes/Part_1_1.stl" scale="1 1 1" />
            </geometry>
            <material name="0.917647_0.917647_0.917647_0.000000_0.000000">
                <color rgba="0.917647 0.917647 0.917647 1" />
            </material>
        </visual>
    </link>
    <link name="part_1_10">
        <inertial>
            <mass value="1.44519" />
            <origin xyz="-5.14675e-20 -0.0155742 7.67044e-19" rpy="0 -0 0" />
            <inertia ixx="0.00149915" ixy="0" ixz="0" iyy="0.0023982" iyz="0" izz="0.00147356" />
        </inertial>
        <visual>
            <origin xyz="0 0 -3.67394e-18" rpy="0 -0 0" />
            <geometry>
                <mesh filename="package://main_assembly/meshes/Part_1.stl" scale="1 1 1" />
            </geometry>
            <material name="0.000000_0.000000_0.000000_0.000000_0.000000">
                <color rgba="0 0 0 1" />
            </material>
        </visual>
    </link>
    <link name="part_1_11">
        <inertial>
            <mass value="0.407095" />
            <origin xyz="-0.0112533 1.51448e-11 0.00267895" rpy="0 -0 0" />
            <inertia ixx="0.000481123" ixy="2.25543e-14" ixz="-1.90394e-05" iyy="0.000433006" iyz="-9.90123e-13" izz="0.000426059" />
        </inertial>
        <visual>
            <origin xyz="-0.05 0 -1.46958e-18" rpy="0 -0 0" />
            <geometry>
                <mesh filename="package://main_assembly/meshes/Part_1_3.stl" scale="1 1 1" />
            </geometry>
            <material name="0.647059_0.647059_0.647059_0.000000_0.000000">
                <color rgba="0.647059 0.647059 0.647059 1" />
            </material>
        </visual>
    </link>
    <link name="part_1_12">
        <inertial>
            <mass value="0.624139" />
            <origin xyz="-0.00242603 0.00723202 -0.0923513" rpy="0 -0 0" />
            <inertia ixx="0.00130765" ixy="-3.92812e-06" ixz="-2.13262e-05" iyy="0.000605235" iyz="6.94147e-05" izz="0.00116478" />
        </inertial>
        <visual>
            <origin xyz="6.30072e-18 -8.44616e-19 -0.09" rpy="0 -0 0" />
            <geometry>
                <mesh filename="package://main_assembly/meshes/Part_1_6.stl" scale="1 1 1" />
            </geometry>
            <material name="0.917647_0.917647_0.917647_0.000000_0.000000">
                <color rgba="0.917647 0.917647 0.917647 1" />
            </material>
        </visual>
    </link>
    <link name="part_1_13">
        <inertial>
            <mass value="0.190836" />
            <origin xyz="0.0425 -2.56394e-13 0.0195886" rpy="0 -0 0" />
            <inertia ixx="5.87597e-05" ixy="1.41175e-14" ixz="0" iyy="0.000682215" iyz="0" izz="0.000651498" />
        </inertial>
        <visual>
            <origin xyz="0.0425 0.015 0.005" rpy="0 -0 0" />
            <geometry>
                <mesh filename="package://main_assembly/meshes/Part_1_1.stl" scale="1 1 1" />
            </geometry>
            <material name="0.917647_0.917647_0.917647_0.000000_0.000000">
                <color rgba="0.917647 0.917647 0.917647 1" />
            </material>
        </visual>
    </link>
    <link name="part_1_14">
        <inertial>
            <mass value="0.600456" />
            <origin xyz="0.00765702 -0.025273 -0.0477765" rpy="0 -0 0" />
            <inertia ixx="0.0027087" ixy="7.68453e-05" ixz="0.00024718" iyy="0.00255143" iyz="-0.000484913" izz="0.00103515" />
        </inertial>
        <visual>
            <origin xyz="0 0 -3.73517e-18" rpy="0 -0 0" />
            <geometry>
                <mesh filename="package://main_assembly/meshes/Part_1_7.stl" scale="1 1 1" />
            </geometry>
            <material name="0.917647_0.917647_0.917647_0.000000_0.000000">
                <color rgba="0.917647 0.917647 0.917647 1" />
            </material>
        </visual>
    </link>
    <link name="part_1_15">
        <inertial>
            <mass value="0.7166" />
            <origin xyz="0.0305 -0.0602366 -3.2147e-19" rpy="0 -0 0" />
            <inertia ixx="0.00192361" ixy="0" ixz="0" iyy="0.00111602" iyz="0" izz="0.00186979" />
        </inertial>
        <visual>
            <origin xyz="0.0305 0.015 -3.2147e-19" rpy="0 -0 0" />
            <geometry>
                <mesh filename="package://main_assembly/meshes/Part_1_4.stl" scale="1 1 1" />
            </geometry>
            <material name="0.647059_0.647059_0.647059_0.000000_0.000000">
                <color rgba="0.647059 0.647059 0.647059 1" />
            </material>
        </visual>
    </link>
    <link name="part_1_16">
        <inertial>
            <mass value="1.44519" />
            <origin xyz="-5.14675e-20 -0.0155742 7.67044e-19" rpy="0 -0 0" />
            <inertia ixx="0.00149915" ixy="0" ixz="0" iyy="0.0023982" iyz="0" izz="0.00147356" />
        </inertial>
        <visual>
            <origin xyz="0 0 -3.67394e-18" rpy="0 -0 0" />
            <geometry>
                <mesh filename="package://main_assembly/meshes/Part_1.stl" scale="1 1 1" />
            </geometry>
            <material name="0.000000_0.000000_0.000000_0.000000_0.000000">
                <color rgba="0 0 0 1" />
            </material>
        </visual>
    </link>
    <link name="part_1_17">
        <inertial>
            <mass value="0.7166" />
            <origin xyz="-0.0305 -0.0602366 -3.2147e-19" rpy="0 -0 0" />
            <inertia ixx="0.00192361" ixy="0" ixz="0" iyy="0.00111602" iyz="0" izz="0.00186979" />
        </inertial>
        <visual>
            <origin xyz="-0.0305 0.015 -3.2147e-19" rpy="0 -0 0" />
            <geometry>
                <mesh filename="package://main_assembly/meshes/Part_1_4.stl" scale="1 1 1" />
            </geometry>
            <material name="0.647059_0.647059_0.647059_0.000000_0.000000">
                <color rgba="0.647059 0.647059 0.647059 1" />
            </material>
        </visual>
    </link>
    <link name="part_1_18">
        <inertial>
            <mass value="0.503498" />
            <origin xyz="0.00966108 -0.0619937 9.92829e-13" rpy="0 -0 0" />
            <inertia ixx="0.00221746" ixy="0.000299204" ixz="-2.58896e-14" iyy="0.000483167" iyz="-7.96788e-15" izz="0.00203993" />
        </inertial>
        <visual>
            <origin xyz="0 1.19354e-19 -3.80442e-18" rpy="0 -0 0" />
            <geometry>
                <mesh filename="package://main_assembly/meshes/Part_1_5.stl" scale="1 1 1" />
            </geometry>
            <material name="0.917647_0.917647_0.917647_0.000000_0.000000">
                <color rgba="0.917647 0.917647 0.917647 1" />
            </material>
        </visual>
    </link>
    <link name="part_1_19">
        <inertial>
            <mass value="0.624139" />
            <origin xyz="-0.00242603 0.00723202 -0.0923513" rpy="0 -0 0" />
            <inertia ixx="0.00130765" ixy="-3.92812e-06" ixz="-2.13262e-05" iyy="0.000605235" iyz="6.94147e-05" izz="0.00116478" />
        </inertial>
        <visual>
            <origin xyz="6.30072e-18 -8.44616e-19 -0.09" rpy="0 -0 0" />
            <geometry>
                <mesh filename="package://main_assembly/meshes/Part_1_6.stl" scale="1 1 1" />
            </geometry>
            <material name="0.917647_0.917647_0.917647_0.000000_0.000000">
                <color rgba="0.917647 0.917647 0.917647 1" />
            </material>
        </visual>
    </link>
    <link name="part_1_2">
        <inertial>
            <mass value="1.44519" />
            <origin xyz="-5.14675e-20 -0.0155742 7.67044e-19" rpy="0 -0 0" />
            <inertia ixx="0.00149915" ixy="0" ixz="0" iyy="0.0023982" iyz="0" izz="0.00147356" />
        </inertial>
        <visual>
            <origin xyz="0 0 -3.67394e-18" rpy="0 -0 0" />
            <geometry>
                <mesh filename="package://main_assembly/meshes/Part_1.stl" scale="1 1 1" />
            </geometry>
            <material name="0.000000_0.000000_0.000000_0.000000_0.000000">
                <color rgba="0 0 0 1" />
            </material>
        </visual>
    </link>
    <link name="part_1_20">
        <inertial>
            <mass value="0.407095" />
            <origin xyz="-0.0112533 1.51448e-11 0.00267895" rpy="0 -0 0" />
            <inertia ixx="0.000481123" ixy="2.25543e-14" ixz="-1.90394e-05" iyy="0.000433006" iyz="-9.90123e-13" izz="0.000426059" />
        </inertial>
        <visual>
            <origin xyz="-0.05 0 -1.46958e-18" rpy="0 -0 0" />
            <geometry>
                <mesh filename="package://main_assembly/meshes/Part_1_3.stl" scale="1 1 1" />
            </geometry>
            <material name="0.647059_0.647059_0.647059_0.000000_0.000000">
                <color rgba="0.647059 0.647059 0.647059 1" />
            </material>
        </visual>
    </link>
    <link name="part_1_21">
        <inertial>
            <mass value="1.44519" />
            <origin xyz="-1.42253e-18 -0.0155742 -2.524e-18" rpy="0 -0 0" />
            <inertia ixx="0.00149915" ixy="0" ixz="0" iyy="0.0023982" iyz="0" izz="0.00147356" />
        </inertial>
        <visual>
            <origin xyz="-1.37106e-18 0 -6.96499e-18" rpy="0 -0 0" />
            <geometry>
                <mesh filename="package://main_assembly/meshes/Part_1.stl" scale="1 1 1" />
            </geometry>
            <material name="0.000000_0.000000_0.000000_0.000000_0.000000">
                <color rgba="0 0 0 1" />
            </material>
        </visual>
    </link>
    <link name="part_1_22">
        <inertial>
            <mass value="1.44519" />
            <origin xyz="-5.14675e-20 -0.0155742 7.67044e-19" rpy="0 -0 0" />
            <inertia ixx="0.00149915" ixy="0" ixz="0" iyy="0.0023982" iyz="0" izz="0.00147356" />
        </inertial>
        <visual>
            <origin xyz="0 0 -3.67394e-18" rpy="0 -0 0" />
            <geometry>
                <mesh filename="package://main_assembly/meshes/Part_1.stl" scale="1 1 1" />
            </geometry>
            <material name="0.000000_0.000000_0.000000_0.000000_0.000000">
                <color rgba="0 0 0 1" />
            </material>
        </visual>
    </link>
    <link name="part_1_3">
        <inertial>
            <mass value="0.542323" />
            <origin xyz="0.000120474 0.00338722 -0.0461384" rpy="0 -0 0" />
            <inertia ixx="0.00189574" ixy="-8.24071e-07" ixz="3.97646e-06" iyy="0.00216313" iyz="0.000288401" izz="0.000585197" />
        </inertial>
        <visual>
            <origin xyz="0 0 -3.73517e-18" rpy="0 -0 0" />
            <geometry>
                <mesh filename="package://main_assembly/meshes/Part_1_2.stl" scale="1 1 1" />
            </geometry>
            <material name="0.917647_0.917647_0.917647_0.000000_0.000000">
                <color rgba="0.917647 0.917647 0.917647 1" />
            </material>
        </visual>
    </link>
    <link name="part_1_4">
        <inertial>
            <mass value="0.407095" />
            <origin xyz="-0.0112533 1.51448e-11 0.00267895" rpy="0 -0 0" />
            <inertia ixx="0.000481123" ixy="2.25543e-14" ixz="-1.90394e-05" iyy="0.000433006" iyz="-9.90123e-13" izz="0.000426059" />
        </inertial>
        <visual>
            <origin xyz="-0.05 0 -1.46958e-18" rpy="0 -0 0" />
            <geometry>
                <mesh filename="package://main_assembly/meshes/Part_1_3.stl" scale="1 1 1" />
            </geometry>
            <material name="0.647059_0.647059_0.647059_0.000000_0.000000">
                <color rgba="0.647059 0.647059 0.647059 1" />
            </material>
        </visual>
    </link>
    <link name="part_1_5">
        <inertial>
            <mass value="0.7166" />
            <origin xyz="0.0305 -0.0602366 -3.2147e-19" rpy="0 -0 0" />
            <inertia ixx="0.00192361" ixy="0" ixz="0" iyy="0.00111602" iyz="0" izz="0.00186979" />
        </inertial>
        <visual>
            <origin xyz="0.0305 0.015 -3.2147e-19" rpy="0 -0 0" />
            <geometry>
                <mesh filename="package://main_assembly/meshes/Part_1_4.stl" scale="1 1 1" />
            </geometry>
            <material name="0.647059_0.647059_0.647059_0.000000_0.000000">
                <color rgba="0.647059 0.647059 0.647059 1" />
            </material>
        </visual>
    </link>
    <link name="part_1_6">
        <inertial>
            <mass value="0.7166" />
            <origin xyz="0.0305 -0.0602366 -3.2147e-19" rpy="0 -0 0" />
            <inertia ixx="0.00192361" ixy="0" ixz="0" iyy="0.00111602" iyz="0" izz="0.00186979" />
        </inertial>
        <visual>
            <origin xyz="0.0305 0.015 -3.2147e-19" rpy="0 -0 0" />
            <geometry>
                <mesh filename="package://main_assembly/meshes/Part_1_4.stl" scale="1 1 1" />
            </geometry>
            <material name="0.647059_0.647059_0.647059_0.000000_0.000000">
                <color rgba="0.647059 0.647059 0.647059 1" />
            </material>
        </visual>
    </link>
    <link name="part_1_7">
        <inertial>
            <mass value="0.407095" />
            <origin xyz="-0.0112533 1.51448e-11 0.00267895" rpy="0 -0 0" />
            <inertia ixx="0.000481123" ixy="2.25543e-14" ixz="-1.90394e-05" iyy="0.000433006" iyz="-9.90123e-13" izz="0.000426059" />
        </inertial>
        <visual>
            <origin xyz="-0.05 0 -1.46958e-18" rpy="0 -0 0" />
            <geometry>
                <mesh filename="package://main_assembly/meshes/Part_1_3.stl" scale="1 1 1" />
            </geometry>
            <material name="0.647059_0.647059_0.647059_0.000000_0.000000">
                <color rgba="0.647059 0.647059 0.647059 1" />
            </material>
        </visual>
    </link>
    <link name="part_1_8">
        <inertial>
            <mass value="0.542323" />
            <origin xyz="0.000120474 0.00338722 -0.0461384" rpy="0 -0 0" />
            <inertia ixx="0.00189574" ixy="-8.24071e-07" ixz="3.97646e-06" iyy="0.00216313" iyz="0.000288401" izz="0.000585197" />
        </inertial>
        <visual>
            <origin xyz="1.98924e-20 0 -3.92377e-18" rpy="0 -0 0" />
            <geometry>
                <mesh filename="package://main_assembly/meshes/Part_1_2.stl" scale="1 1 1" />
            </geometry>
            <material name="0.917647_0.917647_0.917647_0.000000_0.000000">
                <color rgba="0.917647 0.917647 0.917647 1" />
            </material>
        </visual>
    </link>
    <link name="part_1_9">
        <inertial>
            <mass value="0.503498" />
            <origin xyz="0.00966108 -0.0619937 9.92829e-13" rpy="0 -0 0" />
            <inertia ixx="0.00221746" ixy="0.000299204" ixz="-2.58896e-14" iyy="0.000483167" iyz="-7.96789e-15" izz="0.00203993" />
        </inertial>
        <visual>
            <origin xyz="0 1.19354e-19 -3.80442e-18" rpy="0 -0 0" />
            <geometry>
                <mesh filename="package://main_assembly/meshes/Part_1_5.stl" scale="1 1 1" />
            </geometry>
            <material name="0.917647_0.917647_0.917647_0.000000_0.000000">
                <color rgba="0.917647 0.917647 0.917647 1" />
            </material>
        </visual>
    </link>
    <link name="part_2">
        <inertial>
            <mass value="0.600456" />
            <origin xyz="0.00765702 0.025273 -0.0477765" rpy="0 -0 0" />
            <inertia ixx="0.0027087" ixy="-7.68453e-05" ixz="0.00024718" iyy="0.00255143" iyz="0.000484913" izz="0.00103515" />
        </inertial>
        <visual>
            <origin xyz="0 -0.04 -3.73517e-18" rpy="0 -0 0" />
            <geometry>
                <mesh filename="package://main_assembly/meshes/Part_2.stl" scale="1 1 1" />
            </geometry>
            <material name="0.917647_0.917647_0.917647_0.000000_0.000000">
                <color rgba="0.917647 0.917647 0.917647 1" />
            </material>
        </visual>
    </link>
    <link name="part_2_2">
        <inertial>
            <mass value="0.495832" />
            <origin xyz="0.0147745 -0.000171639 -0.0798539" rpy="0 -0 0" />
            <inertia ixx="0.00231557" ixy="-1.70705e-07" ixz="0.000233924" iyy="0.00188039" iyz="2.39148e-06" izz="0.000775428" />
        </inertial>
        <visual>
            <origin xyz="3.46945e-18 -0.016 0.235" rpy="0 -0 0" />
            <geometry>
                <mesh filename="package://main_assembly/meshes/Part_2_2.stl" scale="1 1 1" />
            </geometry>
            <material name="0.917647_0.917647_0.917647_0.000000_0.000000">
                <color rgba="0.917647 0.917647 0.917647 1" />
            </material>
        </visual>
    </link>
    <link name="part_2_4">
        <inertial>
            <mass value="0.495832" />
            <origin xyz="0.0147745 -0.000171639 -0.0798539" rpy="0 -0 0" />
            <inertia ixx="0.00231557" ixy="-1.70705e-07" ixz="0.000233924" iyy="0.00188039" iyz="2.39148e-06" izz="0.000775428" />
        </inertial>
        <visual>
            <origin xyz="3.46945e-18 -0.016 0.235" rpy="0 -0 0" />
            <geometry>
                <mesh filename="package://main_assembly/meshes/Part_2_2.stl" scale="1 1 1" />
            </geometry>
            <material name="0.917647_0.917647_0.917647_0.000000_0.000000">
                <color rgba="0.917647 0.917647 0.917647 1" />
            </material>
        </visual>
    </link>
    <link name="root">
        <visual>
            <origin xyz="-0.553785 -0.104576 0.206518" rpy="0 -0 0" />
            <geometry>
                <mesh filename="package://main_assembly/meshes/Part_2_1.stl" scale="1 1 1" />
            </geometry>
            <material name="0.615686_0.811765_0.929412_0.000000_0.000000">
                <color rgba="0.615686 0.811765 0.929412 1" />
            </material>
        </visual>
        <visual>
            <origin xyz="-0.0319946 0.0915417 0.261464" rpy="0 -0 0" />
            <geometry>
                <mesh filename="package://main_assembly/meshes/Part_2_1.stl" scale="1 1 1" />
            </geometry>
            <material name="0.615686_0.811765_0.929412_0.000000_0.000000">
                <texture />
                <color rgba="0.615686 0.811765 0.929412 1" />
            </material>
        </visual>
    </link>
    <joint name="fastened_1" type="fixed">
        <origin xyz="0.016 6.93889e-18 -0.08" rpy="0 1.5708 -4.71239" />
        <axis xyz="0 1 0" />
        <parent link="hip_joint_aluminium_rect_v13_1" />
        <child link="part_1_22" />
    </joint>
    <joint name="fastened_10" type="fixed">
        <origin xyz="0.0305 -0.175 1.38778e-17" rpy="-1.5708 -2.22045e-16 -1.5708" />
        <axis xyz="1 0 0" />
        <parent link="part_1_6" />
        <child link="part_1_7" />
    </joint>
    <joint name="fastened_11" type="fixed">
        <origin xyz="2.77556e-16 2.08167e-17 0" rpy="0 -1.5708 -3.61175e-17" />
        <axis xyz="0 0 1" />
        <parent link="part_1_7" />
        <child link="part_2_4" />
    </joint>
    <joint name="fastened_12" type="fixed">
        <origin xyz="0.025 1.31839e-16 -0.134306" rpy="0 1.5708 -1.5708" />
        <axis xyz="0 1 0" />
        <parent link="part_2_2" />
        <child link="part_1_2" />
    </joint>
    <joint name="fastened_13" type="fixed">
        <origin xyz="-0.0525426 0.0424644 0.078" rpy="1.15648e-16 -1.2326e-32 -1.5708" />
        <axis xyz="0 1.15648e-16 1" />
        <parent link="hip_joint_aluminium_rect_v13" />
        <child link="part_1_13" />
    </joint>
    <joint name="fastened_14" type="fixed">
        <origin xyz="0.025 -2.08167e-17 -0.134306" rpy="0 1.5708 -1.5708" />
        <axis xyz="0 1 0" />
        <parent link="part_2_4" />
        <child link="part_1_21" />
    </joint>
    <joint name="fastened_15" type="fixed">
        <origin xyz="-0.01 -0.1235 -2.08167e-17" rpy="3.65013e-15 1.3993e-16 1.36881e-17" />
        <axis xyz="1 0 1.60128e-16" />
        <parent link="part_1_9" />
        <child link="part_1_5" />
    </joint>
    <joint name="fastened_16" type="fixed">
        <origin xyz="0.0305 -0.175 1.38778e-17" rpy="1.17586e-15 1.49732e-15 -1.5708" />
        <axis xyz="1 0 0" />
        <parent link="part_1_5" />
        <child link="part_1_20" />
    </joint>
    <joint name="fastened_17" type="fixed">
        <origin xyz="0.015 2.22045e-16 0.005" rpy="-1.5708 -8.88178e-16 1.5708" />
        <axis xyz="0 0 1" />
        <parent link="part_1_20" />
        <child link="part_1_19" />
    </joint>
    <joint name="fastened_18" type="fixed">
        <origin xyz="-0.01 -0.1235 -2.77556e-17" rpy="-3.14159 -1.99827e-16 -3.14159" />
        <axis xyz="-1 0 -1.60128e-16" />
        <parent link="part_1_18" />
        <child link="part_1_17" />
    </joint>
    <joint name="fastened_19" type="fixed">
        <origin xyz="0.0525426 0.0424644 -0.002" rpy="-1.2326e-32 1.58603e-16 1.5708" />
        <axis xyz="-1.58603e-16 0 1" />
        <parent link="hip_joint_aluminium_rect_v13_1" />
        <child link="part_1_1" />
    </joint>
    <joint name="fastened_2" type="fixed">
        <origin xyz="0.03 0.016 -0.107" rpy="1.5708 -1.10624e-15 3.14159" />
        <axis xyz="1 0 1.60128e-16" />
        <parent link="part_1_8" />
        <child link="part_1_15" />
    </joint>
    <joint name="fastened_20" type="fixed">
        <origin xyz="-0.0305 -0.175 0" rpy="-1.5708 -0 -1.5708" />
        <axis xyz="1 0 0" />
        <parent link="part_1_17" />
        <child link="part_1_11" />
    </joint>
    <joint name="fastened_21" type="fixed">
        <origin xyz="0.015 4.85723e-17 0.005" rpy="0 -1.5708 -3.15537e-17" />
        <axis xyz="0 0 1" />
        <parent link="part_1_11" />
        <child link="part_1_12" />
    </joint>
    <joint name="fastened_3" type="fixed">
        <origin xyz="0.0305 -0.175 0" rpy="1.5708 2.10942e-15 -1.5708" />
        <axis xyz="1 0 0" />
        <parent link="part_1_15" />
        <child link="part_1_4" />
    </joint>
    <joint name="fastened_4" type="fixed">
        <origin xyz="5.55112e-17 6.93889e-18 0" rpy="0 -1.5708 1.11077e-16" />
        <axis xyz="0 0 1" />
        <parent link="part_1_4" />
        <child link="part_2_2" />
    </joint>
    <joint name="fastened_5" type="fixed">
        <origin xyz="0 0 -0.08" rpy="0 -0 0" />
        <axis xyz="1 0 0" />
        <parent link="hip_joint_aluminium_rect_v13_1" />
        <child link="hip_joint_aluminium_rect_v13" />
    </joint>
    <joint name="fastened_6" type="fixed">
        <origin xyz="-0.016 6.93889e-18 0" rpy="0 -1.5708 4.71239" />
        <axis xyz="0 1 0" />
        <parent link="hip_joint_aluminium_rect_v13" />
        <child link="part_1_10" />
    </joint>
    <joint name="fastened_7" type="fixed">
        <origin xyz="0.02 0.0462922 -0.11817" rpy="3.14159 3.46945e-18 1.5708" />
        <axis xyz="0 1 0" />
        <parent link="part_2" />
        <child link="part_1_16" />
    </joint>
    <joint name="fastened_8" type="fixed">
        <origin xyz="0.02 -0.0462922 -0.11817" rpy="-3.14159 -1.42177e-17 1.5708" />
        <axis xyz="0 1 0" />
        <parent link="part_1_14" />
        <child link="part_1" />
    </joint>
    <joint name="fastened_9" type="fixed">
        <origin xyz="0.03 0.016 -0.107" rpy="1.5708 1.98168e-16 -3.14159" />
        <axis xyz="1 0 1.60128e-16" />
        <parent link="part_1_3" />
        <child link="part_1_6" />
    </joint>
    <joint name="fixed_node_to_root_joint" type="fixed">
        <origin xyz="-0.240875 -0.0458792 0.168557" rpy="0 -0 0" />
        <axis xyz="0 0 1" />
        <parent link="root" />
        <child link="hip_joint_aluminium_rect_v13_1" />
    </joint>
    <joint name="revolute_1" type="revolute">
        <origin xyz="0 -0.04 -6.93889e-18" rpy="0 1.5708 -3.14159" />
        <axis xyz="0 -1 0" />
        <parent link="part_1_22" />
        <child link="part_2" />
        <limit effort="1" velocity="1" lower="-1.74533" upper="1.74533" />
    </joint>
    <joint name="revolute_2" type="revolute">
        <origin xyz="0 -0.04 -6.93889e-18" rpy="0 1.5708 -4.47559e-16" />
        <axis xyz="0 1 0" />
        <parent link="part_1_10" />
        <child link="part_1_14" />
        <limit effort="1" velocity="1" lower="-1.74533" upper="1.74533" />
    </joint>
    <joint name="revolute_3" type="revolute">
        <origin xyz="0 -0.04 -3.46945e-18" rpy="3.14159 -2.39462e-17 3.14159" />
        <axis xyz="0 1 0" />
        <parent link="part_1" />
        <child link="part_1_3" />
        <limit effort="1" velocity="1" lower="-1.74533" upper="0.174533" />
    </joint>
    <joint name="revolute_4" type="revolute">
        <origin xyz="0 -0.04 0" rpy="3.14159 8.67362e-19 -3.14159" />
        <axis xyz="0 1 0" />
        <parent link="part_1_16" />
        <child link="part_1_8" />
        <limit effort="1" velocity="1" lower="-0.174533" upper="1.74533" />
    </joint>
    <joint name="revolute_5" type="revolute">
        <origin xyz="0 -0.04 6.93889e-18" rpy="2.08182e-14 -5.20151e-16 1.5708" />
        <axis xyz="1 -0 -0" />
        <parent link="part_1_2" />
        <child link="part_1_18" />
        <limit effort="1" velocity="1" lower="-1.74533" upper="1.74533" />
    </joint>
    <joint name="revolute_6" type="revolute">
        <origin xyz="0 -0.04 1.38778e-17" rpy="2.79623e-14 5.45768e-17 1.5708" />
        <axis xyz="1 -0 -0" />
        <parent link="part_1_21" />
        <child link="part_1_9" />
        <limit effort="1" velocity="1" lower="-1.74533" upper="1.74533" />
    </joint>
</robot>
